Workbook
Name _18650_: 'Formula 2'!$A$5:$A$7
Name Battery_Packaging: 'Formula 2'!$E$26:$E$37
Name Lithium_cobalt_oxide: 'Formula 2'!$A$9:$A$11
Name Lithium_Ion: 'Formula 2'!$A$13:$A$15
Name Lithium_iron_phosphate: 'Formula 2'!$A$17:$A$19
Name Lithium_nickel_manganese_cobalt_oxide: 'Formula 2'!$A$21:$A$23
Name Lithium_Polymer: 'Formula 2'!$C$5:$C$7
Name Lithium_titanate: 'Formula 2'!$C$9:$C$11
Name Multiple_cells: 'Formula 2'!$K$9:$K$12
Name Single_cell: 'Formula 2'!$K$5:$K$7
Name Yes: 'Formula 2'!$A$26:$A$47

Sheet Battery exemption sheet
A10: What are Dangerous Goods? | F10: Examples of Dangerous Goods | H10: Declaration table for products that need batteries to function or that are batteries themselves: Please fill the below information in sequence
A11: A product will be regulated as dangerous good if any of its components are classified as dangerous goods or substances or are otherwise regulated by any official organization that governs safe transport, storage, or handling of goods. For more information on dangerous goods, please consult the Dangerous Goods Identification Guide in Seller Central Help.
I12: ASIN | J12: Product title | K12: What's in the box? | L12: Are batteries sold with the product or is the product a battery? | M12: Chemical composition / cell type of the battery | N12: Battery packaging | O12: No. of cells | P12: Watt-hours | Q12: Spillability | R12: Details validation status
I13: B0H4ZH5TSR | J13: Porodo Thumb-Sized Digital Camera Memo II, Mini Spy Cam, 1080P HD Video Recording, TF Card Support, USB-C Charging, 0.96" Display, One-Key Recording, Audio Output, Fill Light, Yellow | K13: Security Camera | L13: Yes | M13: Lithium_Ion | N13: In Equipment | O13: Single_cell | P13: WH <= 20 | R13: =IF(LEN($W13)>0,IF($X$13=TRUE,"Please enter first and last name",W13),"") | W13: =IF(LEN($L13&$M13&$N13&$O13&$P13&$Q13)>0,IF(ISERROR(VLOOKUP($L13&$M13&$N13&$O13&$P13&$Q13,Formula!$H:$O,8,0)),"Incomplete",(VLOOKUP($L13&$M13&$N13&$O13&$P13&$Q13,Formula!$H:$O,8,0))),"") | X13: =OR(LEN($D$24)>0,LEN($G$24)>0)
R14: =IF(LEN($W14)>0,IF($X$13=TRUE,"Please enter first and last name",W14),"") | W14: =IF(LEN($L14&$M14&$N14&$O14&$P14&$Q14)>0,IF(ISERROR(VLOOKUP($L14&$M14&$N14&$O14&$P14&$Q14,Formula!$H:$O,8,0)),"Incomplete",(VLOOKUP($L14&$M14&$N14&$O14&$P14&$Q14,Formula!$H:$O,8,0))),"")
R15: =IF(LEN($W15)>0,IF($X$13=TRUE,"Please enter first and last name",W15),"") | W15: =IF(LEN($L15&$M15&$N15&$O15&$P15&$Q15)>0,IF(ISERROR(VLOOKUP($L15&$M15&$N15&$O15&$P15&$Q15,Formula!$H:$O,8,0)),"Incomplete",(VLOOKUP($L15&$M15&$N15&$O15&$P15&$Q15,Formula!$H:$O,8,0))),"")
A16: Important note: This exemption sheet is required and will be accepted only for products that may need batteries to function (even if the batteries are not included with the product or if the product is to be plugged-in) or that are batteries themselves. If your product does not belong to that category but is otherwise regulated as dangerous good or contains chemicals and/or substances (e.g. cleaners, essential oils, paint related products), please provide a Safety Data Sheet (to be obtained from your manufacturer) instead of a battery exemption sheet. This exemption sheet must be completely filled out before being submitted: all cells in red must be informed, across all 2 pages (move to the right). For complete instructions, please go to the Instructions tab of this Excel file. | R16: =IF(LEN($W16)>0,IF($X$13=TRUE,"Please enter first and last name",W16),"") | W16: =IF(LEN($L16&$M16&$N16&$O16&$P16&$Q16)>0,IF(ISERROR(VLOOKUP($L16&$M16&$N16&$O16&$P16&$Q16,Formula!$H:$O,8,0)),"Incomplete",(VLOOKUP($L16&$M16&$N16&$O16&$P16&$Q16,Formula!$H:$O,8,0))),"")
R17: =IF(LEN($W17)>0,IF($X$13=TRUE,"Please enter first and last name",W17),"") | W17: =IF(LEN($L17&$M17&$N17&$O17&$P17&$Q17)>0,IF(ISERROR(VLOOKUP($L17&$M17&$N17&$O17&$P17&$Q17,Formula!$H:$O,8,0)),"Incomplete",(VLOOKUP($L17&$M17&$N17&$O17&$P17&$Q17,Formula!$H:$O,8,0))),"")
R18: =IF(LEN($W18)>0,IF($X$13=TRUE,"Please enter first and last name",W18),"") | W18: =IF(LEN($L18&$M18&$N18&$O18&$P18&$Q18)>0,IF(ISERROR(VLOOKUP($L18&$M18&$N18&$O18&$P18&$Q18,Formula!$H:$O,8,0)),"Incomplete",(VLOOKUP($L18&$M18&$N18&$O18&$P18&$Q18,Formula!$H:$O,8,0))),"")
R19: =IF(LEN($W19)>0,IF($X$13=TRUE,"Please enter first and last name",W19),"") | W19: =IF(LEN($L19&$M19&$N19&$O19&$P19&$Q19)>0,IF(ISERROR(VLOOKUP($L19&$M19&$N19&$O19&$P19&$Q19,Formula!$H:$O,8,0)),"Incomplete",(VLOOKUP($L19&$M19&$N19&$O19&$P19&$Q19,Formula!$H:$O,8,0))),"")
R20: =IF(LEN($W20)>0,IF($X$13=TRUE,"Please enter first and last name",W20),"") | W20: =IF(LEN($L20&$M20&$N20&$O20&$P20&$Q20)>0,IF(ISERROR(VLOOKUP($L20&$M20&$N20&$O20&$P20&$Q20,Formula!$H:$O,8,0)),"Incomplete",(VLOOKUP($L20&$M20&$N20&$O20&$P20&$Q20,Formula!$H:$O,8,0))),"")
R21: =IF(LEN($W21)>0,IF($X$13=TRUE,"Please enter first and last name",W21),"") | W21: =IF(LEN($L21&$M21&$N21&$O21&$P21&$Q21)>0,IF(ISERROR(VLOOKUP($L21&$M21&$N21&$O21&$P21&$Q21,Formula!$H:$O,8,0)),"Incomplete",(VLOOKUP($L21&$M21&$N21&$O21&$P21&$Q21,Formula!$H:$O,8,0))),"")
R22: =IF(LEN($W22)>0,IF($X$13=TRUE,"Please enter first and last name",W22),"") | W22: =IF(LEN($L22&$M22&$N22&$O22&$P22&$Q22)>0,IF(ISERROR(VLOOKUP($L22&$M22&$N22&$O22&$P22&$Q22,Formula!$H:$O,8,0)),"Incomplete",(VLOOKUP($L22&$M22&$N22&$O22&$P22&$Q22,Formula!$H:$O,8,0))),"")
R23: =IF(LEN($W23)>0,IF($X$13=TRUE,"Please enter first and last name",W23),"") | W23: =IF(LEN($L23&$M23&$N23&$O23&$P23&$Q23)>0,IF(ISERROR(VLOOKUP($L23&$M23&$N23&$O23&$P23&$Q23,Formula!$H:$O,8,0)),"Incomplete",(VLOOKUP($L23&$M23&$N23&$O23&$P23&$Q23,Formula!$H:$O,8,0))),"")
D24: =IF(LEN($D$25)=0,"Please enter 'First Name'","") | G24: =IF(LEN($G$25)=0,"Please enter 'Last Name'","") | R24: =IF(LEN($W24)>0,IF($X$13=TRUE,"Please enter first and last name",W24),"") | W24: =IF(LEN($L24&$M24&$N24&$O24&$P24&$Q24)>0,IF(ISERROR(VLOOKUP($L24&$M24&$N24&$O24&$P24&$Q24,Formula!$H:$O,8,0)),"Incomplete",(VLOOKUP($L24&$M24&$N24&$O24&$P24&$Q24,Formula!$H:$O,8,0))),"")
A25: Date: | B25: =TODAY() | C25: First name: | D25: Nima | F25: Last name: | G25: Zare | R25: =IF(LEN($W25)>0,IF($X$13=TRUE,"Please enter first and last name",W25),"") | W25: =IF(LEN($L25&$M25&$N25&$O25&$P25&$Q25)>0,IF(ISERROR(VLOOKUP($L25&$M25&$N25&$O25&$P25&$Q25,Formula!$H:$O,8,0)),"Incomplete",(VLOOKUP($L25&$M25&$N25&$O25&$P25&$Q25,Formula!$H:$O,8,0))),"")
C26: Please enter your first and last name. If a company name is entered, the exemption sheet will be rejected | R26: =IF(LEN($W26)>0,IF($X$13=TRUE,"Please enter first and last name",W26),"") | W26: =IF(LEN($L26&$M26&$N26&$O26&$P26&$Q26)>0,IF(ISERROR(VLOOKUP($L26&$M26&$N26&$O26&$P26&$Q26,Formula!$H:$O,8,0)),"Incomplete",(VLOOKUP($L26&$M26&$N26&$O26&$P26&$Q26,Formula!$H:$O,8,0))),"")
R27: =IF(LEN($W27)>0,IF($X$13=TRUE,"Please enter first and last name",W27),"") | W27: =IF(LEN($L27&$M27&$N27&$O27&$P27&$Q27)>0,IF(ISERROR(VLOOKUP($L27&$M27&$N27&$O27&$P27&$Q27,Formula!$H:$O,8,0)),"Incomplete",(VLOOKUP($L27&$M27&$N27&$O27&$P27&$Q27,Formula!$H:$O,8,0))),"")
A28: Disclaimer: By submitting this document to Amazon, you hereby confirm that you have checked the regulations applicable to your product and that the information you provide is correct. In the case of erroneous or incomplete information provided through this exemption sheet, Amazon reserves its right to take the corresponding actions without prior notice. These actions may include but are not limited to: blocked purchase order placement, classification and inbounding delays, and disposal of existing inventory at your expense. | R28: =IF(LEN($W28)>0,IF($X$13=TRUE,"Please enter first and last name",W28),"") | W28: =IF(LEN($L28&$M28&$N28&$O28&$P28&$Q28)>0,IF(ISERROR(VLOOKUP($L28&$M28&$N28&$O28&$P28&$Q28,Formula!$H:$O,8,0)),"Incomplete",(VLOOKUP($L28&$M28&$N28&$O28&$P28&$Q28,Formula!$H:$O,8,0))),"")
R29: =IF(LEN($W29)>0,IF($X$13=TRUE,"Please enter first and last name",W29),"") | W29: =IF(LEN($L29&$M29&$N29&$O29&$P29&$Q29)>0,IF(ISERROR(VLOOKUP($L29&$M29&$N29&$O29&$P29&$Q29,Formula!$H:$O,8,0)),"Incomplete",(VLOOKUP($L29&$M29&$N29&$O29&$P29&$Q29,Formula!$H:$O,8,0))),"")
R30: =IF(LEN($W30)>0,IF($X$13=TRUE,"Please enter first and last name",W30),"") | W30: =IF(LEN($L30&$M30&$N30&$O30&$P30&$Q30)>0,IF(ISERROR(VLOOKUP($L30&$M30&$N30&$O30&$P30&$Q30,Formula!$H:$O,8,0)),"Incomplete",(VLOOKUP($L30&$M30&$N30&$O30&$P30&$Q30,Formula!$H:$O,8,0))),"")
R31: =IF(LEN($W31)>0,IF($X$13=TRUE,"Please enter first and last name",W31),"") | W31: =IF(LEN($L31&$M31&$N31&$O31&$P31&$Q31)>0,IF(ISERROR(VLOOKUP($L31&$M31&$N31&$O31&$P31&$Q31,Formula!$H:$O,8,0)),"Incomplete",(VLOOKUP($L31&$M31&$N31&$O31&$P31&$Q31,Formula!$H:$O,8,0))),"")
R32: =IF(LEN($W32)>0,IF($X$13=TRUE,"Please enter first and last name",W32),"") | W32: =IF(LEN($L32&$M32&$N32&$O32&$P32&$Q32)>0,IF(ISERROR(VLOOKUP($L32&$M32&$N32&$O32&$P32&$Q32,Formula!$H:$O,8,0)),"Incomplete",(VLOOKUP($L32&$M32&$N32&$O32&$P32&$Q32,Formula!$H:$O,8,0))),"")
A34: If there is anything else you would like to tell us about your products, please use this box to share comments

Sheet Instructions
A1: SR.No | B1: Exemption sheet for Battery and battery-powered products - Instructions
B4: This exemption sheet will be accepted for 5 ASINs maximum.
B6: New Instructions
A8: 1 | B8: ASIN column should contain 10 digit alphanumeric number or system wil not accept the entry.
A18: 2
B19: Example of Valid Combination
B29: Information updated correctly when you get "Complete " in Details Validation Status
A31: 3
B32: Example of incomplete information.
B42: Important note: Cells in Pink must be filled out, and cells in BLACK must be left empty. (Highlighted BLACK field should not be tampered)
A45: 4 | B45: How to Delete the data from drop down
B46: To delete the data from a row select “Blank” from drop down in revers pattern. i.e. from Spillabilityà Watt-hoursà No. of cells-à Battery packagingà Chemical composition
A61: 5
B62: 1. Fill out your first and last name in the corresponding fields. Do not enter your company name:
A70: 6 | B70: Enter the ASIN of your product (e.g. B0023M098N). Do not enter the UPC / EAN / FNSKU or the product name, only the ASIN:
A80: 7 | B80: If your product is not a kit (does not come with additional battery or battery-powered devices): Enter the name of your product, as it appears on the detail page (Amazon webpage)
B93: Important note: Do not copy/paste the product name directly from the detail page. Type it in instead, otherwise you may experience formatting issues.
A97: 8 | B97: If your product is a kit. Please mention all the box products that are availabe in the box in section (What's in the box?)
B111: Important note: If your product includes multiple items, you must submit documentation for each item. For example, for a shaving kit with the shaver and a cleaning solution, you must fill out this exemption sheet for the battery item ("shaver") and submit a Safety Data Sheet for the chemical/substance item ("cleaning solution").
A115: 9 | B115: From the drop-down menu, select if the your product (or item within a kit) is sold with a battery / batteries or not. Select "Yes" even if the battery is not removable and/or non-rechargeable. If your product does not contain / is not a battery itself / is not sold with any batteries, then select "No":
B127: Important note: If you select "No" to the "Are batteries sold with the product or is the product a battery?" question, then do not fill out any other columns (battery chemical composition, battery packaging, etc.). If you do, the exemption sheet will be rejected as conflicting.
A131: 10 | B131: If you answered "Yes" to the "Are batteries sold with the product or is the product a battery?", please select from the drop-down menu what battery composition / type your product is / contains / is sold with:
B141: If you have selected a lithium composition or type (CR2032, CR123A, CR123, lithium metal, lithium ion, 18650-Li-ion, lithium polymer) or lead acid/ lead calcium in column M, you must select a battery packaging type in the drop-down menu. Please select the packaging based on the definitions below:
A142: 11
B145: a. Select "In equipment" if the battery is preinstalled or assembled in the item (e.g. Kindle tablet or Apple i phone)
B146: b. Select "With equipment" if the battery is packed with, but not inside, the device it powers. For example, a cell phone with the removable battery packed alongside the phone. If your product has both a battery preinstalled in the device (e.g. tablet) and a battery packed alongside (e.g. spare battery for the tablet), then select "With equipment"
B149: c. Select "Standalone" if the product is a battery sold alone (e.g. replacement laptop battery) or if the battery is sold with items that it does not power (e.g. a spare cell phone battery sold with a charger). External battery chargers (e.g. powerbanks) are standalone batteries
A172: 12 | B172: If you have selected a lithium-ion composition or type (lithium ion, 18650-Li-ion, lithium polymer) in column M, you must also provide the energy content in watt-hours (Wh) of your product. The Wh can usually be found printed on the battery itself or in the product's manual. It can also be calculated from the battery nominal voltage (V) and amp-hour (Ah) rating. A Wh calculator is available at the link below:
C176: Off line calclucation | H176: Current Rating
B177: Online calclucation link | E177: Voltage | H177: in Ah | J177: =F178*I177
B178: Wh calculator | E178: Volt (V) | H178: OR | K178: WH | L178: =IF(J177>0,J177,J179)
H179: in mAh | J179: =F178*(I179/1000)
E180: Do not calculate WH if your product is a POWER BANK or JUMP STARTER
B193: Important note: If you selected a battery composition or type other than lithium-ion in column M, do not fill out the "Watt-hours" column If you do, the exemption sheet will be rejected as conflicting.
A196: 13 | B196: If you have selected a Lead Acid/Lead Calcium composition in column M, you must let us know if the lead acid/ lead calcium battery is spillable or not. To know if your lead acid battery product is spillable or not, refer to the product manual. If you select "non-spillable", then the battery itself must be plainly and durably marked "non-spillable" or "non-spillable battery". Also please provide battery packaging as well in coloumn "N"
B211: Important note: If you selected a battery composition other than Lead Acid in column m, do not fill out the "Spillability" column If you do, the exemption sheet will be rejected as conflicting.

Sheet Formula
A1: Are batteries sold with the product or is the product a battery? | B1: Chemical composition / cell type of the battery | C1: Battery packaging | D1: Watt-hours | E1: Spillability | I1: Are batteries sold with the product or is the product a battery? | J1: Chemical composition / cell type of the battery | K1: Battery packaging | L1: No. of cells | M1: Watt-hours | N1: Spillability | O1: Possible classification as per ES SOP
A2: Yes | B2: _18650_ | C2: In Equipment | D2: WH <= 100 | E2: Spillable | H2: =I2&J2&K2&L2&M2&N2 | I2: No | O2: Complete
A3: No | B3: Alkaline | C3: With Equipment | D3: 101 - 300 WH | E3: Non-Spillable | H3: =I3&J3&K3&L3&M3&N3 | I3: Yes | J3: Alkaline | O3: Complete
B4: Carbon Zinc | C4: Standalone | D4: WH > 300 | H4: =I4&J4&K4&L4&M4&N4 | I4: Yes | J4: Nickel_Metal_Hydride | O4: Complete
B5: CR2032 | H5: =I5&J5&K5&L5&M5&N5 | I5: Yes | J5: Nickel_Cadmium | O5: Complete
B6: Lead Acid | H6: =I6&J6&K6&L6&M6&N6 | I6: Yes | J6: Zinc_Carbon | O6: Complete
B7: Lead Calcium | H7: =I7&J7&K7&L7&M7&N7 | I7: Yes | J7: Zinc_air | O7: Complete
B8: Lithium cobalt oxide | H8: =I8&J8&K8&L8&M8&N8 | I8: Yes | J8: Silver_Oxide | O8: Complete
B9: Lithium Ion | H9: =I9&J9&K9&L9&M9&N9 | I9: Yes | J9: Lithium_Ion | K9: In equipment | O9: Incomplete
B10: Lithium iron phosphate | H10: =I10&J10&K10&L10&M10&N10 | I10: Yes | J10: Lithium_Metal | K10: In equipment | O10: Complete
B11: Lithium Metal | H11: =I11&J11&K11&L11&M11&N11 | I11: Yes | J11: Lithium_Ion | K11: With equipment | O11: Incomplete
B12: Lithium nickel manganese cobalt oxide | H12: =I12&J12&K12&L12&M12&N12 | I12: Yes | J12: Lithium_Metal | K12: With equipment | O12: Complete
B13: Lithium Polymer | H13: =I13&J13&K13&L13&M13&N13 | I13: Yes | J13: Lithium_Ion | K13: Standalone | O13: Incomplete
B14: Lithium thionyl chloride | H14: =I14&J14&K14&L14&M14&N14 | I14: Yes | J14: Lithium_Metal | K14: Standalone | O14: Complete
B15: Lithium titanate | H15: =I15&J15&K15&L15&M15&N15 | I15: Yes | J15: Lithium_Ion | M15: =IF('Battery exemption sheet'!$P$13>0,'Battery exemption sheet'!$P$13," ") | O15: Incomplete
B16: LR44 | H16: =I16&J16&K16&L16&M16&N16 | I16: Yes | J16: Lithium_Ion | O16: Incomplete
B17: Nickel Cadmium | H17: =I17&J17&K17&L17&M17&N17 | I17: Yes | J17: Lithium_Metal | O17: Incomplete
B18: Nickel Metal Hydride | H18: =I18&J18&K18&L18&M18&N18 | I18: Yes | J18: Lead_Acid | K18: In equipment | N18: Non-spillable | O18: Complete
B19: Silver Oxide | H19: =I19&J19&K19&L19&M19&N19 | I19: Yes | J19: Lead_Acid | K19: In equipment | N19: Spillable | O19: Complete
B20: Zinc | H20: =I20&J20&K20&L20&M20&N20 | I20: Yes | J20: Lead_Acid | O20: Incomplete
B21: Zinc air | H21: =I21&J21&K21&L21&M21&N21 | I21: Yes | J21: Lead_Calcium | K21: In equipment | N21: Non-spillable | O21: Complete
B22: Zinc Carbon | H22: =I22&J22&K22&L22&M22&N22 | I22: Yes | J22: Lead_Calcium | K22: In equipment | N22: Spillable | O22: Complete
H23: =I23&J23&K23&L23&M23&N23 | I23: Yes | J23: Lead_Calcium | O23: Incomplete
H24: =I24&J24&K24&L24&M24&N24 | I24: Yes | J24: Lithium_Metal | O24: Incomplete
H25: =I25&J25&K25&L25&M25&N25 | I25: Yes | J25: Lithium_Polymer | K25: In equipment | O25: Incomplete
A26: ! | H26: =I26&J26&K26&L26&M26&N26 | I26: Yes | J26: Lithium_Polymer | K26: With equipment | O26: Incomplete
A27: @ | H27: =I27&J27&K27&L27&M27&N27 | I27: Yes | J27: Lithium_Polymer | K27: Standalone | O27: Incomplete
A28: # | H28: =I28&J28&K28&L28&M28&N28 | I28: Yes | J28: Lithium_Polymer | M28: =IF('Battery exemption sheet'!$P$13>0,'Battery exemption sheet'!$P$13," ") | O28: Incomplete
A29: $ | H29: =I29&J29&K29&L29&M29&N29 | I29: Yes | J29: Lithium_Polymer | O29: Incomplete
A30: % | H30: =I30&J30&K30&L30&M30&N30 | I30: Yes | J30: Zinc | O30: Complete
A31: ^ | H31: =I31&J31&K31&L31&M31&N31 | I31: No | J31: Alkaline | O31: Incomplete
A32: & | H32: =I32&J32&K32&L32&M32&N32 | I32: No | J32: Nickel_Metal_Hydride | O32: Incomplete
A33: * | H33: =I33&J33&K33&L33&M33&N33 | I33: No | J33: Nickel_Cadmium | O33: Incomplete
H34: =I34&J34&K34&L34&M34&N34 | I34: No | J34: Zinc_Carbon | O34: Incomplete
H35: =I35&J35&K35&L35&M35&N35 | I35: No | J35: Zinc_air | O35: Incomplete
H36: =I36&J36&K36&L36&M36&N36 | I36: No | J36: Silver_Oxide | O36: Incomplete
H37: =I37&J37&K37&L37&M37&N37 | I37: No | J37: Lithium_Ion | K37: In equipment | M37: =IF('Battery exemption sheet'!$P$13>0,'Battery exemption sheet'!$P$13," ") | O37: Incomplete
H38: =I38&J38&K38&L38&M38&N38 | I38: No | J38: Lithium_Ion | K38: In equipment | O38: Incomplete
H39: =I39&J39&K39&L39&M39&N39 | I39: No | J39: Lithium_Metal | K39: In equipment | O39: Incomplete
H40: =I40&J40&K40&L40&M40&N40 | I40: No | J40: Lithium_Ion | K40: With equipment | O40: Incomplete
...

Sheet Formula 2
A4: _18650_ | C4: Lithium_Polymer | E4: Lead_Acid | K4: Single_cell
A5: Single_cell | C5: Single_cell | E5: Spillable | K5: WH <= 20
A6: Multiple_cells | C6: Multiple_cells | E6: Non-Spillable | K6: WH > 20
A8: Lithium_cobalt_oxide | C8: Lithium_titanate | E8: Lead_Calcium | K8: Multiple_cells
A9: Single_cell | C9: Single_cell | E9: Spillable | K9: WH <= 100
A10: Multiple_cells | C10: Multiple_cells | E10: Non-Spillable | K10: 101 - 300 WH
K11: WH > 300
A12: Lithium_Ion
A13: Single_cell
A14: Multiple_cells
A16: Lithium_iron_phosphate
A17: Single_cell
A18: Multiple_cells | E18: Battery Packaging ON/OFF | G18: Spillability | I18: ASIN/Title
E19: =OR('Battery exemption sheet'!M13="_18650_",'Battery exemption sheet'!M13="Lithium_cobalt_oxide",'Battery exemption sheet'!M13="Lithium_Ion",'Battery exemption sheet'!M13="Lithium_iron_phosphate",'Battery exemption sheet'!M13="Lithium_nickel_manganese_cobalt_oxide",'Battery exemption sheet'!M13="Lithium_Polymer",'Battery exemption sheet'!M13="Lithium_titanate",'Battery exemption sheet'!M13="Lithium_Metal",'Battery exemption sheet'!M13="_CR2032_",'Battery exemption sheet'!M13="Lithium_thionyl_chloride",'Battery exemption sheet'!M13="Lead_Acid",'Battery exemption sheet'!M13="Lead_Calcium") | G19: =OR('Battery exemption sheet'!M13="Lead_Acid",'Battery exemption sheet'!M13="Lead_Calcium") | I19: =OR(LEN('Battery exemption sheet'!K13)>0)
A20: Lithium_nickel_manganese_cobalt_oxide | E20: =OR('Battery exemption sheet'!M14="_18650_",'Battery exemption sheet'!M14="Lithium_cobalt_oxide",'Battery exemption sheet'!M14="Lithium_Ion",'Battery exemption sheet'!M14="Lithium_iron_phosphate",'Battery exemption sheet'!M14="Lithium_nickel_manganese_cobalt_oxide",'Battery exemption sheet'!M14="Lithium_Polymer",'Battery exemption sheet'!M14="Lithium_titanate",'Battery exemption sheet'!M14="Lithium_Metal",'Battery exemption sheet'!M14="_CR2032_",'Battery exemption sheet'!M14="Lithium_thionyl_chloride",'Battery exemption sheet'!M14="Lead_Acid",'Battery exemption sheet'!M14="Lead_Calcium") | G20: =OR('Battery exemption sheet'!M14="Lead_Acid",'Battery exemption sheet'!M14="Lead_Calcium") | I20: =OR(LEN('Battery exemption sheet'!K14)>0)
A21: Single_cell | E21: =OR('Battery exemption sheet'!M15="_18650_",'Battery exemption sheet'!M15="Lithium_cobalt_oxide",'Battery exemption sheet'!M15="Lithium_Ion",'Battery exemption sheet'!M15="Lithium_iron_phosphate",'Battery exemption sheet'!M15="Lithium_nickel_manganese_cobalt_oxide",'Battery exemption sheet'!M15="Lithium_Polymer",'Battery exemption sheet'!M15="Lithium_titanate",'Battery exemption sheet'!M15="Lithium_Metal",'Battery exemption sheet'!M15="_CR2032_",'Battery exemption sheet'!M15="Lithium_thionyl_chloride",'Battery exemption sheet'!M15="Lead_Acid",'Battery exemption sheet'!M15="Lead_Calcium") | G21: =OR('Battery exemption sheet'!M15="Lead_Acid",'Battery exemption sheet'!M15="Lead_Calcium") | I21: =OR(LEN('Battery exemption sheet'!K15)>0)
A22: Multiple_cells | E22: =OR('Battery exemption sheet'!M16="_18650_",'Battery exemption sheet'!M16="Lithium_cobalt_oxide",'Battery exemption sheet'!M16="Lithium_Ion",'Battery exemption sheet'!M16="Lithium_iron_phosphate",'Battery exemption sheet'!M16="Lithium_nickel_manganese_cobalt_oxide",'Battery exemption sheet'!M16="Lithium_Polymer",'Battery exemption sheet'!M16="Lithium_titanate",'Battery exemption sheet'!M16="Lithium_Metal",'Battery exemption sheet'!M16="_CR2032_",'Battery exemption sheet'!M16="Lithium_thionyl_chloride",'Battery exemption sheet'!M16="Lead_Acid",'Battery exemption sheet'!M16="Lead_Calcium") | G22: =OR('Battery exemption sheet'!M16="Lead_Acid",'Battery exemption sheet'!M16="Lead_Calcium") | I22: =OR(LEN('Battery exemption sheet'!K16)>0)
E23: =OR('Battery exemption sheet'!M17="_18650_",'Battery exemption sheet'!M17="Lithium_cobalt_oxide",'Battery exemption sheet'!M17="Lithium_Ion",'Battery exemption sheet'!M17="Lithium_iron_phosphate",'Battery exemption sheet'!M17="Lithium_nickel_manganese_cobalt_oxide",'Battery exemption sheet'!M17="Lithium_Polymer",'Battery exemption sheet'!M17="Lithium_titanate",'Battery exemption sheet'!M17="Lithium_Metal",'Battery exemption sheet'!M17="_CR2032_",'Battery exemption sheet'!M17="Lithium_thionyl_chloride",'Battery exemption sheet'!M17="Lead_Acid",'Battery exemption sheet'!M17="Lead_Calcium") | G23: =OR('Battery exemption sheet'!M17="Lead_Acid",'Battery exemption sheet'!M17="Lead_Calcium") | I23: =OR(LEN('Battery exemption sheet'!K17)>0)
E24: =OR('Battery exemption sheet'!M18="_18650_",'Battery exemption sheet'!M18="Lithium_cobalt_oxide",'Battery exemption sheet'!M18="Lithium_Ion",'Battery exemption sheet'!M18="Lithium_iron_phosphate",'Battery exemption sheet'!M18="Lithium_nickel_manganese_cobalt_oxide",'Battery exemption sheet'!M18="Lithium_Polymer",'Battery exemption sheet'!M18="Lithium_titanate",'Battery exemption sheet'!M18="Lithium_Metal",'Battery exemption sheet'!M18="_CR2032_",'Battery exemption sheet'!M18="Lithium_thionyl_chloride",'Battery exemption sheet'!M18="Lead_Acid",'Battery exemption sheet'!M18="Lead_Calcium") | G24: =OR('Battery exemption sheet'!M18="Lead_Acid",'Battery exemption sheet'!M18="Lead_Calcium") | I24: =OR(LEN('Battery exemption sheet'!K18)>0)
A25: Yes | B25: No | E25: =OR('Battery exemption sheet'!M19="_18650_",'Battery exemption sheet'!M19="Lithium_cobalt_oxide",'Battery exemption sheet'!M19="Lithium_Ion",'Battery exemption sheet'!M19="Lithium_iron_phosphate",'Battery exemption sheet'!M19="Lithium_nickel_manganese_cobalt_oxide",'Battery exemption sheet'!M19="Lithium_Polymer",'Battery exemption sheet'!M19="Lithium_titanate",'Battery exemption sheet'!M19="Lithium_Metal",'Battery exemption sheet'!M19="_CR2032_",'Battery exemption sheet'!M19="Lithium_thionyl_chloride",'Battery exemption sheet'!M19="Lead_Acid",'Battery exemption sheet'!M19="Lead_Calcium") | G25: =OR('Battery exemption sheet'!M19="Lead_Acid",'Battery exemption sheet'!M19="Lead_Calcium") | I25: =OR(LEN('Battery exemption sheet'!K19)>0)
A26: _18650_ | E26: =OR('Battery exemption sheet'!M20="_18650_",'Battery exemption sheet'!M20="Lithium_cobalt_oxide",'Battery exemption sheet'!M20="Lithium_Ion",'Battery exemption sheet'!M20="Lithium_iron_phosphate",'Battery exemption sheet'!M20="Lithium_nickel_manganese_cobalt_oxide",'Battery exemption sheet'!M20="Lithium_Polymer",'Battery exemption sheet'!M20="Lithium_titanate",'Battery exemption sheet'!M20="Lithium_Metal",'Battery exemption sheet'!M20="_CR2032_",'Battery exemption sheet'!M20="Lithium_thionyl_chloride",'Battery exemption sheet'!M20="Lead_Acid",'Battery exemption sheet'!M20="Lead_Calcium") | G26: =OR('Battery exemption sheet'!M20="Lead_Acid",'Battery exemption sheet'!M20="Lead_Calcium") | I26: =OR(LEN('Battery exemption sheet'!K20)>0)
A27: Lithium_cobalt_oxide | E27: =OR('Battery exemption sheet'!M21="_18650_",'Battery exemption sheet'!M21="Lithium_cobalt_oxide",'Battery exemption sheet'!M21="Lithium_Ion",'Battery exemption sheet'!M21="Lithium_iron_phosphate",'Battery exemption sheet'!M21="Lithium_nickel_manganese_cobalt_oxide",'Battery exemption sheet'!M21="Lithium_Polymer",'Battery exemption sheet'!M21="Lithium_titanate",'Battery exemption sheet'!M21="Lithium_Metal",'Battery exemption sheet'!M21="_CR2032_",'Battery exemption sheet'!M21="Lithium_thionyl_chloride",'Battery exemption sheet'!M21="Lead_Acid",'Battery exemption sheet'!M21="Lead_Calcium") | G27: =OR('Battery exemption sheet'!M21="Lead_Acid",'Battery exemption sheet'!M21="Lead_Calcium") | I27: =OR(LEN('Battery exemption sheet'!K21)>0)
A28: Lithium_Ion | E28: =OR('Battery exemption sheet'!M22="_18650_",'Battery exemption sheet'!M22="Lithium_cobalt_oxide",'Battery exemption sheet'!M22="Lithium_Ion",'Battery exemption sheet'!M22="Lithium_iron_phosphate",'Battery exemption sheet'!M22="Lithium_nickel_manganese_cobalt_oxide",'Battery exemption sheet'!M22="Lithium_Polymer",'Battery exemption sheet'!M22="Lithium_titanate",'Battery exemption sheet'!M22="Lithium_Metal",'Battery exemption sheet'!M22="_CR2032_",'Battery exemption sheet'!M22="Lithium_thionyl_chloride",'Battery exemption sheet'!M22="Lead_Acid",'Battery exemption sheet'!M22="Lead_Calcium") | G28: =OR('Battery exemption sheet'!M22="Lead_Acid",'Battery exemption sheet'!M22="Lead_Calcium") | I28: =OR(LEN('Battery exemption sheet'!K22)>0)
A29: Lithium_iron_phosphate | E29: =OR('Battery exemption sheet'!M23="_18650_",'Battery exemption sheet'!M23="Lithium_cobalt_oxide",'Battery exemption sheet'!M23="Lithium_Ion",'Battery exemption sheet'!M23="Lithium_iron_phosphate",'Battery exemption sheet'!M23="Lithium_nickel_manganese_cobalt_oxide",'Battery exemption sheet'!M23="Lithium_Polymer",'Battery exemption sheet'!M23="Lithium_titanate",'Battery exemption sheet'!M23="Lithium_Metal",'Battery exemption sheet'!M23="_CR2032_",'Battery exemption sheet'!M23="Lithium_thionyl_chloride",'Battery exemption sheet'!M23="Lead_Acid",'Battery exemption sheet'!M23="Lead_Calcium") | G29: =OR('Battery exemption sheet'!M23="Lead_Acid",'Battery exemption sheet'!M23="Lead_Calcium") | I29: =OR(LEN('Battery exemption sheet'!K23)>0)
A30: Lithium_nickel_manganese_cobalt_oxide | E30: =OR('Battery exemption sheet'!M24="_18650_",'Battery exemption sheet'!M24="Lithium_cobalt_oxide",'Battery exemption sheet'!M24="Lithium_Ion",'Battery exemption sheet'!M24="Lithium_iron_phosphate",'Battery exemption sheet'!M24="Lithium_nickel_manganese_cobalt_oxide",'Battery exemption sheet'!M24="Lithium_Polymer",'Battery exemption sheet'!M24="Lithium_titanate",'Battery exemption sheet'!M24="Lithium_Metal",'Battery exemption sheet'!M24="_CR2032_",'Battery exemption sheet'!M24="Lithium_thionyl_chloride",'Battery exemption sheet'!M24="Lead_Acid",'Battery exemption sheet'!M24="Lead_Calcium") | G30: =OR('Battery exemption sheet'!M24="Lead_Acid",'Battery exemption sheet'!M24="Lead_Calcium") | I30: =OR(LEN('Battery exemption sheet'!K24)>0)
A31: Lithium_Polymer | E31: =OR('Battery exemption sheet'!M25="_18650_",'Battery exemption sheet'!M25="Lithium_cobalt_oxide",'Battery exemption sheet'!M25="Lithium_Ion",'Battery exemption sheet'!M25="Lithium_iron_phosphate",'Battery exemption sheet'!M25="Lithium_nickel_manganese_cobalt_oxide",'Battery exemption sheet'!M25="Lithium_Polymer",'Battery exemption sheet'!M25="Lithium_titanate",'Battery exemption sheet'!M25="Lithium_Metal",'Battery exemption sheet'!M25="_CR2032_",'Battery exemption sheet'!M25="Lithium_thionyl_chloride",'Battery exemption sheet'!M25="Lead_Acid",'Battery exemption sheet'!M25="Lead_Calcium") | G31: =OR('Battery exemption sheet'!M25="Lead_Acid",'Battery exemption sheet'!M25="Lead_Calcium") | I31: =OR(LEN('Battery exemption sheet'!K25)>0)
A32: Lithium_titanate | E32: =OR('Battery exemption sheet'!M26="_18650_",'Battery exemption sheet'!M26="Lithium_cobalt_oxide",'Battery exemption sheet'!M26="Lithium_Ion",'Battery exemption sheet'!M26="Lithium_iron_phosphate",'Battery exemption sheet'!M26="Lithium_nickel_manganese_cobalt_oxide",'Battery exemption sheet'!M26="Lithium_Polymer",'Battery exemption sheet'!M26="Lithium_titanate",'Battery exemption sheet'!M26="Lithium_Metal",'Battery exemption sheet'!M26="_CR2032_",'Battery exemption sheet'!M26="Lithium_thionyl_chloride",'Battery exemption sheet'!M26="Lead_Acid",'Battery exemption sheet'!M26="Lead_Calcium") | G32: =OR('Battery exemption sheet'!M26="Lead_Acid",'Battery exemption sheet'!M26="Lead_Calcium") | I32: =OR(LEN('Battery exemption sheet'!K26)>0)
A33: Lithium_Metal | E33: =OR('Battery exemption sheet'!M27="_18650_",'Battery exemption sheet'!M27="Lithium_cobalt_oxide",'Battery exemption sheet'!M27="Lithium_Ion",'Battery exemption sheet'!M27="Lithium_iron_phosphate",'Battery exemption sheet'!M27="Lithium_nickel_manganese_cobalt_oxide",'Battery exemption sheet'!M27="Lithium_Polymer",'Battery exemption sheet'!M27="Lithium_titanate",'Battery exemption sheet'!M27="Lithium_Metal",'Battery exemption sheet'!M27="_CR2032_",'Battery exemption sheet'!M27="Lithium_thionyl_chloride",'Battery exemption sheet'!M27="Lead_Acid",'Battery exemption sheet'!M27="Lead_Calcium") | G33: =OR('Battery exemption sheet'!M27="Lead_Acid",'Battery exemption sheet'!M27="Lead_Calcium") | I33: =OR(LEN('Battery exemption sheet'!K27)>0)
A34: Lithium_thionyl_chloride | E34: =OR('Battery exemption sheet'!M28="_18650_",'Battery exemption sheet'!M28="Lithium_cobalt_oxide",'Battery exemption sheet'!M28="Lithium_Ion",'Battery exemption sheet'!M28="Lithium_iron_phosphate",'Battery exemption sheet'!M28="Lithium_nickel_manganese_cobalt_oxide",'Battery exemption sheet'!M28="Lithium_Polymer",'Battery exemption sheet'!M28="Lithium_titanate",'Battery exemption sheet'!M28="Lithium_Metal",'Battery exemption sheet'!M28="_CR2032_",'Battery exemption sheet'!M28="Lithium_thionyl_chloride",'Battery exemption sheet'!M28="Lead_Acid",'Battery exemption sheet'!M28="Lead_Calcium") | G34: =OR('Battery exemption sheet'!M28="Lead_Acid",'Battery exemption sheet'!M28="Lead_Calcium") | I34: =OR(LEN('Battery exemption sheet'!K28)>0)
A35: _LR44_ | E35: =OR('Battery exemption sheet'!M29="_18650_",'Battery exemption sheet'!M29="Lithium_cobalt_oxide",'Battery exemption sheet'!M29="Lithium_Ion",'Battery exemption sheet'!M29="Lithium_iron_phosphate",'Battery exemption sheet'!M29="Lithium_nickel_manganese_cobalt_oxide",'Battery exemption sheet'!M29="Lithium_Polymer",'Battery exemption sheet'!M29="Lithium_titanate",'Battery exemption sheet'!M29="Lithium_Metal",'Battery exemption sheet'!M29="_CR2032_",'Battery exemption sheet'!M29="Lithium_thionyl_chloride",'Battery exemption sheet'!M29="Lead_Acid",'Battery exemption sheet'!M29="Lead_Calcium") | G35: =OR('Battery exemption sheet'!M29="Lead_Acid",'Battery exemption sheet'!M29="Lead_Calcium") | I35: =OR(LEN('Battery exemption sheet'!K29)>0)
A36: Alkaline | E36: =OR('Battery exemption sheet'!M30="_18650_",'Battery exemption sheet'!M30="Lithium_cobalt_oxide",'Battery exemption sheet'!M30="Lithium_Ion",'Battery exemption sheet'!M30="Lithium_iron_phosphate",'Battery exemption sheet'!M30="Lithium_nickel_manganese_cobalt_oxide",'Battery exemption sheet'!M30="Lithium_Polymer",'Battery exemption sheet'!M30="Lithium_titanate",'Battery exemption sheet'!M30="Lithium_Metal",'Battery exemption sheet'!M30="_CR2032_",'Battery exemption sheet'!M30="Lithium_thionyl_chloride",'Battery exemption sheet'!M30="Lead_Acid",'Battery exemption sheet'!M30="Lead_Calcium") | G36: =OR('Battery exemption sheet'!M30="Lead_Acid",'Battery exemption sheet'!M30="Lead_Calcium") | I36: =OR(LEN('Battery exemption sheet'!K30)>0)
A37: Carbon_Zinc | E37: =OR('Battery exemption sheet'!M31="_18650_",'Battery exemption sheet'!M31="Lithium_cobalt_oxide",'Battery exemption sheet'!M31="Lithium_Ion",'Battery exemption sheet'!M31="Lithium_iron_phosphate",'Battery exemption sheet'!M31="Lithium_nickel_manganese_cobalt_oxide",'Battery exemption sheet'!M31="Lithium_Polymer",'Battery exemption sheet'!M31="Lithium_titanate",'Battery exemption sheet'!M31="Lithium_Metal",'Battery exemption sheet'!M31="_CR2032_",'Battery exemption sheet'!M31="Lithium_thionyl_chloride",'Battery exemption sheet'!M31="Lead_Acid",'Battery exemption sheet'!M31="Lead_Calcium") | G37: =OR('Battery exemption sheet'!M31="Lead_Acid",'Battery exemption sheet'!M31="Lead_Calcium") | I37: =OR(LEN('Battery exemption sheet'!K31)>0)
A38: _CR2032_ | E38: =OR('Battery exemption sheet'!M32="_18650_",'Battery exemption sheet'!M32="Lithium_cobalt_oxide",'Battery exemption sheet'!M32="Lithium_Ion",'Battery exemption sheet'!M32="Lithium_iron_phosphate",'Battery exemption sheet'!M32="Lithium_nickel_manganese_cobalt_oxide",'Battery exemption sheet'!M32="Lithium_Polymer",'Battery exemption sheet'!M32="Lithium_titanate",'Battery exemption sheet'!M32="Lithium_Metal",'Battery exemption sheet'!M32="_CR2032_",'Battery exemption sheet'!M32="Lithium_thionyl_chloride",'Battery exemption sheet'!M32="Lead_Acid",'Battery exemption sheet'!M32="Lead_Calcium") | G38: =OR('Battery exemption sheet'!M32="Lead_Acid",'Battery exemption sheet'!M32="Lead_Calcium") | I38: =OR(LEN('Battery exemption sheet'!K32)>0)
A39: Lead_Acid
A40: Lead_Calcium
A41: Nickel_Cadmium
A42: Nickel_Metal_Hydride
A43: Silver_Oxide
A44: Zinc
A45: Zinc_air
...
